<?xml version="1.0" ?>
<!-- =================================================================================== -->
<!-- |    This document was autogenerated by xacro from /home/vboxuser/orca_robot/colcon_ws/src/OrcaRL2/simulation/ros2_boldbot/boldbot_description/urdf/boldbot.urdf.xacro | -->
<!-- |    EDITING THIS FILE BY HAND IS NOT RECOMMENDED                                 | -->
<!-- =================================================================================== -->
<robot name="boldbot">
  <!-- <xacro:macro name="xmass" params="value"><mass value="1" /></xacro:macro> -->
  <!-- <xacro:macro name="inertial_cuboid" params="mass xyz rpy x_length y_length z_length"> -->
  <!--   <inertial> -->
  <!--     <xacro:xmass value="1" /> -->
  <!--     <origin xyz="${xyz}" rpy="${rpy}"/> -->
  <!--     <inertia ixx="${1 * (y_length*y_length + z_length*z_length) / 12}" ixy="0.0" ixz="0.0" -->
  <!--              iyy="${1 * (x_length*x_length + z_length*z_length) / 12}" iyz="0.0" -->
  <!--              izz="${1 * (x_length*x_length + y_length*y_length) / 12}" /> -->
  <!--   </inertial> -->
  <!-- </xacro:macro> -->
  <!-- dummy first link, directly connects with torso -->
  <link name="base_link"/>
  <joint name="base_joint" type="fixed">
    <parent link="base_link"/>
    <child link="torso"/>
    <origin rpy="0 0 0" xyz="0 0 0"/>
  </joint>
  <link name="torso">
    <visual>
      <origin rpy="0 0 0" xyz="0 0 0"/>
      <geometry>
        <box size="0.1 0.109 0.045"/>
      </geometry>
    </visual>
    <collision>
      <origin rpy="0 0 0" xyz="0 0 0"/>
      <geometry>
        <box size="0.1 0.109 0.045"/>
      </geometry>
    </collision>
    <inertial>
      <mass value="0.31"/>
      <origin rpy="0 0 0" xyz="0 0 0"/>
      <inertia ixx="0.0003592383333333333" ixy="0.0" ixz="0.0" iyy="0.00031064583333333335" iyz="0.0" izz="0.0005652591666666667"/>
    </inertial>
  </link>
  <gazebo reference="torso">
    <material>Gazebo/Grey</material>
    <selfCollide>true</selfCollide>
  </gazebo>
  <joint name="torso-mx28-head-pan" type="fixed">
    <parent link="torso"/>
    <child link="mx28-head-pan"/>
    <origin rpy="0 0 3.141592653589793" xyz="0.02 0 0.045"/>
  </joint>
  <link name="mx28-head-pan">
    <visual>
      <origin rpy="0 0 0" xyz="0 0 0"/>
      <geometry>
        <mesh filename="package://boldbot_description/meshes/mx28b.stl" scale="0.001 0.001 0.001"/>
      </geometry>
      <material name="DarkGrey">
        <color rgba="0.20 0.20 0.20 1.0"/>
      </material>
    </visual>
    <collision>
      <origin rpy="0 0 0" xyz="0 0 0"/>
      <geometry>
        <mesh filename="package://boldbot_description/meshes/mx28b.stl" scale="0.001 0.001 0.001"/>
      </geometry>
    </collision>
    <inertial>
      <mass value="0.077"/>
      <origin rpy="0 0 0" xyz="0.0105 0 0"/>
      <inertia ixx="1.621883083333333e-05" ixy="0.0" ixz="0.0" iyy="2.451558083333333e-05" iyz="0.0" izz="2.4561203333333333e-05"/>
    </inertial>
  </link>
  <gazebo reference="mx28-head-pan">
    <material>Gazebo/DarkGrey</material>
    <selfCollide>true</selfCollide>
  </gazebo>
  <joint name="head-pan" type="revolute">
    <parent link="mx28-head-pan"/>
    <child link="neck"/>
    <origin rpy="0 0 -3.141592653589793" xyz="0 0 0.02"/>
    <axis xyz="0 0 1"/>
    <limit effort="2.8" lower="-2.6179939" upper="2.6179939" velocity="5.6548668"/>
    <dynamics damping="0" friction="0.1"/>
  </joint>
  <link name="neck">
    <visual>
      <origin rpy="0 0 0" xyz="0 0 0"/>
      <geometry>
        <mesh filename="package://boldbot_description/meshes/neckbracketb.stl" scale="0.001 0.001 0.001"/>
      </geometry>
    </visual>
    <collision>
      &gt;
      
      <origin rpy="0 0 0" xyz="0 0 0"/>
      <geometry>
        <mesh filename="package://boldbot_description/meshes/neckbracketb.stl" scale="0.001 0.001 0.001"/>
      </geometry>
    </collision>
    <inertial>
      <mass value="0.025"/>
      <origin rpy="0 0 0" xyz="0 0 0.029"/>
      <inertia ixx="6.419270833333334e-06" ixy="0.0" ixz="0.0" iyy="3.5026041666666672e-06" iyz="0.0" izz="5.520833333333333e-06"/>
    </inertial>
  </link>
  <joint name="head-tilt" type="revolute">
    <parent link="neck"/>
    <child link="mx28-head-tilt"/>
    <origin rpy="0 -1.5707963267948966 -1.5707963267948966" xyz="0 0 0.03"/>
    <axis xyz="0 0 1"/>
    <limit effort="2.8" lower="-2.6179939" upper="2.6179939" velocity="5.6548668"/>
    <dynamics damping="0" friction="0.1"/>
  </joint>
  <link name="mx28-head-tilt">
    <visual>
      <origin rpy="0 0 0" xyz="0 0 0"/>
      <geometry>
        <mesh filename="package://boldbot_description/meshes/mx28b.stl" scale="0.001 0.001 0.001"/>
      </geometry>
      <material name="DarkGrey">
        <color rgba="0.20 0.20 0.20 1.0"/>
      </material>
    </visual>
    <collision>
      <origin rpy="0 0 0" xyz="0 0 0"/>
      <geometry>
        <mesh filename="package://boldbot_description/meshes/mx28b.stl" scale="0.001 0.001 0.001"/>
      </geometry>
    </collision>
    <inertial>
      <mass value="0.077"/>
      <origin rpy="0 0 0" xyz="0.0105 0 0"/>
      <inertia ixx="1.621883083333333e-05" ixy="0.0" ixz="0.0" iyy="2.451558083333333e-05" iyz="0.0" izz="2.4561203333333333e-05"/>
    </inertial>
  </link>
  <gazebo reference="mx28-head-tilt">
    <material>Gazebo/DarkGrey</material>
    <selfCollide>true</selfCollide>
  </gazebo>
  <joint name="head-tilt-head" type="fixed">
    <parent link="mx28-head-tilt"/>
    <child link="head"/>
    <origin rpy="1.5707963267948966 0 1.5707963267948966" xyz="0.065 0 0"/>
  </joint>
  <link name="head">
    <visual>
      <origin rpy="0 0 0" xyz="0 0 0"/>
      <geometry>
        <box size="0.05 0.1 0.04"/>
      </geometry>
    </visual>
    <collision>
      <origin rpy="0 0 0" xyz="0 0 0"/>
      <geometry>
        <box size="0.05 0.1 0.04"/>
      </geometry>
    </collision>
    <inertial>
      <mass value="0.2"/>
      <origin rpy="0 0 0" xyz="0 0 0"/>
      <inertia ixx="0.00019333333333333336" ixy="0.0" ixz="0.0" iyy="6.833333333333335e-05" iyz="0.0" izz="0.00020833333333333337"/>
    </inertial>
  </link>
  <gazebo reference="head">
    <material>Gazebo/Grey</material>
    <selfCollide>true</selfCollide>
  </gazebo>
  <joint name="head-gaze" type="fixed">
    <parent link="head"/>
    <child link="camera_rgb"/>
    <origin rpy="-1.57 0 -1.57" xyz="0 0 0"/>
  </joint>
  <link name="camera_rgb">
  </link>
  <!-- Arms -->
  <joint name="torso-mx28-shoulder-pitch-l" type="fixed">
    <parent link="torso"/>
    <child link="mx28-shoulder-pitch-l"/>
    <origin rpy="1.5707963267948966 0 3.141592653589793" xyz="0.02 0.04 0.045"/>
  </joint>
  <link name="mx28-shoulder-pitch-l">
    <visual>
      <origin rpy="0 0 0" xyz="0 0 0"/>
      <geometry>
        <mesh filename="package://boldbot_description/meshes/mx28b.stl" scale="0.001 0.001 0.001"/>
      </geometry>
      <material name="DarkGrey">
        <color rgba="0.20 0.20 0.20 1.0"/>
      </material>
    </visual>
    <collision>
      <origin rpy="0 0 0" xyz="0 0 0"/>
      <geometry>
        <mesh filename="package://boldbot_description/meshes/mx28b.stl" scale="0.001 0.001 0.001"/>
      </geometry>
    </collision>
    <inertial>
      <mass value="0.077"/>
      <origin rpy="0 0 0" xyz="0.0105 0 0"/>
      <inertia ixx="1.621883083333333e-05" ixy="0.0" ixz="0.0" iyy="2.451558083333333e-05" iyz="0.0" izz="2.4561203333333333e-05"/>
    </inertial>
  </link>
  <gazebo reference="mx28-shoulder-pitch-l">
    <material>Gazebo/DarkGrey</material>
    <selfCollide>true</selfCollide>
  </gazebo>
  <joint name="shoulder-pitch-l" type="revolute">
    <parent link="mx28-shoulder-pitch-l"/>
    <child link="shoulder-l"/>
    <origin rpy="0 0 0" xyz="0 0 0.02"/>
    <axis xyz="0 0 1"/>
    <limit effort="2.8" lower="-2.6179939" upper="2.6179939" velocity="5.6548668"/>
    <dynamics damping="0" friction="0.1"/>
  </joint>
  <link name="shoulder-l">
    <visual>
      <origin rpy="1.5707963267948966 0 3.141592653589793" xyz="0 0 0"/>
      <geometry>
        <mesh filename="package://boldbot_description/meshes/shoulderbracketb.stl" scale="0.001 0.001 0.001"/>
      </geometry>
    </visual>
    <inertial>
      <mass value="0.025"/>
      <origin rpy="0 0 0" xyz="0 -0.0025 0.018"/>
      <inertia ixx="5.304666666666667e-06" ixy="0.0" ixz="0.0" iyy="7.0416666666666664e-06" iyz="0.0" izz="6.329666666666667e-06"/>
    </inertial>
  </link>
  <joint name="shoulder-roll-l" type="revolute">
    <parent link="shoulder-l"/>
    <child link="mx28-shoulder-roll-l"/>
    <origin rpy="1.5707963267948966 -0.7853981633974483 -1.5707963267948966" xyz="0 -0.016 0.025"/>
    <axis xyz="0 0 1"/>
    <limit effort="2.8" lower="-2.6179939" upper="2.6179939" velocity="5.6548668"/>
    <dynamics damping="0" friction="0.1"/>
  </joint>
  <link name="mx28-shoulder-roll-l">
    <visual>
      <origin rpy="0 0 0" xyz="0 0 0"/>
      <geometry>
        <mesh filename="package://boldbot_description/meshes/mx28b.stl" scale="0.001 0.001 0.001"/>
      </geometry>
      <material name="DarkGrey">
        <color rgba="0.20 0.20 0.20 1.0"/>
      </material>
    </visual>
    <collision>
      <origin rpy="0 0 0" xyz="0 0 0"/>
      <geometry>
        <mesh filename="package://boldbot_description/meshes/mx28b.stl" scale="0.001 0.001 0.001"/>
      </geometry>
    </collision>
    <inertial>
      <mass value="0.077"/>
      <origin rpy="0 0 0" xyz="0.0105 0 0"/>
      <inertia ixx="1.621883083333333e-05" ixy="0.0" ixz="0.0" iyy="2.451558083333333e-05" iyz="0.0" izz="2.4561203333333333e-05"/>
    </inertial>
  </link>
  <gazebo reference="mx28-shoulder-roll-l">
    <material>Gazebo/DarkGrey</material>
    <selfCollide>true</selfCollide>
  </gazebo>
  <joint name="mx28-shoulder-roll-l-mx28-elbow-l" type="fixed">
    <parent link="mx28-shoulder-roll-l"/>
    <child link="mx28-elbow-l"/>
    <origin rpy="-1.5707963267948966 1.5707963267948966 0" xyz="0.06 0 0.016"/>
  </joint>
  <link name="mx28-elbow-l">
    <visual>
      <origin rpy="0 0 0" xyz="0 0 0"/>
      <geometry>
        <mesh filename="package://boldbot_description/meshes/mx28b.stl" scale="0.001 0.001 0.001"/>
      </geometry>
      <material name="DarkGrey">
        <color rgba="0.20 0.20 0.20 1.0"/>
      </material>
    </visual>
    <collision>
      <origin rpy="0 0 0" xyz="0 0 0"/>
      <geometry>
        <mesh filename="package://boldbot_description/meshes/mx28b.stl" scale="0.001 0.001 0.001"/>
      </geometry>
    </collision>
    <inertial>
      <mass value="0.077"/>
      <origin rpy="0 0 0" xyz="0.0105 0 0"/>
      <inertia ixx="1.621883083333333e-05" ixy="0.0" ixz="0.0" iyy="2.451558083333333e-05" iyz="0.0" izz="2.4561203333333333e-05"/>
    </inertial>
  </link>
  <gazebo reference="mx28-elbow-l">
    <material>Gazebo/DarkGrey</material>
    <selfCollide>true</selfCollide>
  </gazebo>
  <joint name="elbow-l" type="revolute">
    <parent link="mx28-elbow-l"/>
    <child link="lower-arm-l"/>
    <origin rpy="0 0 0" xyz="0 0 0"/>
    <axis xyz="0 0 1"/>
    <limit effort="2.8" lower="-2.6179939" upper="2.6179939" velocity="5.6548668"/>
    <dynamics damping="0" friction="0.1"/>
  </joint>
  <link name="lower-arm-l">
    <visual>
      <origin rpy="3.141592653589793 0 3.141592653589793" xyz="-0.055 -0.02 0.02"/>
      <geometry>
        <mesh filename="package://boldbot_description/meshes/armcoverb.stl" scale="0.001 0.001 0.001"/>
      </geometry>
    </visual>
    <collision>
      <origin rpy="3.141592653589793 0 3.141592653589793" xyz="-0.055 -0.02 0.02"/>
      <geometry>
        <mesh filename="package://boldbot_description/meshes/armcoverb.stl" scale="0.001 0.001 0.001"/>
      </geometry>
    </collision>
    <inertial>
      <mass value="0.03538216"/>
      <origin rpy="0 0 0" xyz="-0.085 -0.02 0.014"/>
      <inertia ixx="8.073029506666667e-06" ixy="0.0" ixz="0.0" iyy="6.658111670833332e-05" iyz="0.0" izz="7.153461910833334e-05"/>
    </inertial>
  </link>
  <gazebo reference="lower-arm-l">
    <material>Gazebo/Grey</material>
    <selfCollide>true</selfCollide>
  </gazebo>
  <joint name="torso-mx28-shoulder-pitch-r" type="fixed">
    <parent link="torso"/>
    <child link="mx28-shoulder-pitch-r"/>
    <origin rpy="-1.5707963267948966 0 3.141592653589793" xyz="0.02 -0.04 0.045"/>
  </joint>
  <link name="mx28-shoulder-pitch-r">
    <visual>
      <origin rpy="0 0 0" xyz="0 0 0"/>
      <geometry>
        <mesh filename="package://boldbot_description/meshes/mx28b.stl" scale="0.001 0.001 0.001"/>
      </geometry>
      <material name="DarkGrey">
        <color rgba="0.20 0.20 0.20 1.0"/>
      </material>
    </visual>
    <collision>
      <origin rpy="0 0 0" xyz="0 0 0"/>
      <geometry>
        <mesh filename="package://boldbot_description/meshes/mx28b.stl" scale="0.001 0.001 0.001"/>
      </geometry>
    </collision>
    <inertial>
      <mass value="0.077"/>
      <origin rpy="0 0 0" xyz="0.0105 0 0"/>
      <inertia ixx="1.621883083333333e-05" ixy="0.0" ixz="0.0" iyy="2.451558083333333e-05" iyz="0.0" izz="2.4561203333333333e-05"/>
    </inertial>
  </link>
  <gazebo reference="mx28-shoulder-pitch-r">
    <material>Gazebo/DarkGrey</material>
    <selfCollide>true</selfCollide>
  </gazebo>
  <joint name="shoulder-pitch-r" type="revolute">
    <parent link="mx28-shoulder-pitch-r"/>
    <child link="shoulder-r"/>
    <origin rpy="0 0 0" xyz="0 0 0.02"/>
    <axis xyz="0 0 1"/>
    <limit effort="2.8" lower="-2.6179939" upper="2.6179939" velocity="5.6548668"/>
    <dynamics damping="0" friction="0.1"/>
  </joint>
  <link name="shoulder-r">
    <visual>
      <origin rpy="1.5707963267948966 0 0" xyz="0 0 0"/>
      <geometry>
        <mesh filename="package://boldbot_description/meshes/shoulderbracketb.stl" scale="0.001 0.001 0.001"/>
      </geometry>
    </visual>
    <inertial>
      <mass value="0.025"/>
      <origin rpy="0 0 0" xyz="0 0.0025 0.018"/>
      <inertia ixx="5.304666666666667e-06" ixy="0.0" ixz="0.0" iyy="7.0416666666666664e-06" iyz="0.0" izz="6.329666666666667e-06"/>
    </inertial>
  </link>
  <joint name="shoulder-roll-r" type="revolute">
    <parent link="shoulder-r"/>
    <child link="mx28-shoulder-roll-r"/>
    <origin rpy="-1.5707963267948966 -0.7853981633974483 1.5707963267948966" xyz="0 0.016 0.025"/>
    <axis xyz="0 0 1"/>
    <limit effort="2.8" lower="-2.6179939" upper="2.6179939" velocity="5.6548668"/>
    <dynamics damping="0" friction="0.1"/>
  </joint>
  <link name="mx28-shoulder-roll-r">
    <visual>
      <origin rpy="0 0 0" xyz="0 0 0"/>
      <geometry>
        <mesh filename="package://boldbot_description/meshes/mx28b.stl" scale="0.001 0.001 0.001"/>
      </geometry>
      <material name="DarkGrey">
        <color rgba="0.20 0.20 0.20 1.0"/>
      </material>
    </visual>
    <collision>
      <origin rpy="0 0 0" xyz="0 0 0"/>
      <geometry>
        <mesh filename="package://boldbot_description/meshes/mx28b.stl" scale="0.001 0.001 0.001"/>
      </geometry>
    </collision>
    <inertial>
      <mass value="0.077"/>
      <origin rpy="0 0 0" xyz="0.0105 0 0"/>
      <inertia ixx="1.621883083333333e-05" ixy="0.0" ixz="0.0" iyy="2.451558083333333e-05" iyz="0.0" izz="2.4561203333333333e-05"/>
    </inertial>
  </link>
  <gazebo reference="mx28-shoulder-roll-r">
    <material>Gazebo/DarkGrey</material>
    <selfCollide>true</selfCollide>
  </gazebo>
  <joint name="mx28-shoulder-roll-r-mx28-elbow-r" type="fixed">
    <parent link="mx28-shoulder-roll-r"/>
    <child link="mx28-elbow-r"/>
    <origin rpy="1.5707963267948966 1.5707963267948966 0" xyz="0.06 0 0.016"/>
  </joint>
  <link name="mx28-elbow-r">
    <visual>
      <origin rpy="0 0 0" xyz="0 0 0"/>
      <geometry>
        <mesh filename="package://boldbot_description/meshes/mx28b.stl" scale="0.001 0.001 0.001"/>
      </geometry>
      <material name="DarkGrey">
        <color rgba="0.20 0.20 0.20 1.0"/>
      </material>
    </visual>
    <collision>
      <origin rpy="0 0 0" xyz="0 0 0"/>
      <geometry>
        <mesh filename="package://boldbot_description/meshes/mx28b.stl" scale="0.001 0.001 0.001"/>
      </geometry>
    </collision>
    <inertial>
      <mass value="0.077"/>
      <origin rpy="0 0 0" xyz="0.0105 0 0"/>
      <inertia ixx="1.621883083333333e-05" ixy="0.0" ixz="0.0" iyy="2.451558083333333e-05" iyz="0.0" izz="2.4561203333333333e-05"/>
    </inertial>
  </link>
  <gazebo reference="mx28-elbow-r">
    <material>Gazebo/DarkGrey</material>
    <selfCollide>true</selfCollide>
  </gazebo>
  <joint name="elbow-r" type="revolute">
    <parent link="mx28-elbow-r"/>
    <child link="lower-arm-r"/>
    <origin rpy="0 0 0" xyz="0 0 0"/>
    <axis xyz="0 0 1"/>
    <limit effort="2.8" lower="-2.6179939" upper="2.6179939" velocity="5.6548668"/>
    <dynamics damping="0" friction="0.1"/>
  </joint>
  <link name="lower-arm-r">
    <visual>
      <origin rpy="3.141592653589793 0 3.141592653589793" xyz="-0.055 0.02 0.02"/>
      <geometry>
        <mesh filename="package://boldbot_description/meshes/armcoverb.stl" scale="0.001 0.001 0.001"/>
      </geometry>
    </visual>
    <collision>
      <origin rpy="3.141592653589793 0 3.141592653589793" xyz="-0.055 0.02 0.02"/>
      <geometry>
        <mesh filename="package://boldbot_description/meshes/armcoverb.stl" scale="0.001 0.001 0.001"/>
      </geometry>
    </collision>
    <inertial>
      <mass value="0.03538216"/>
      <origin rpy="0 0 0" xyz="-0.085 0.02 0.014"/>
      <inertia ixx="8.073029506666667e-06" ixy="0.0" ixz="0.0" iyy="6.658111670833332e-05" iyz="0.0" izz="7.153461910833334e-05"/>
    </inertial>
  </link>
  <gazebo reference="lower-arm-r">
    <material>Gazebo/Grey</material>
    <selfCollide>true</selfCollide>
  </gazebo>
  <!-- Legs -->
  <joint name="torso-mx28-hip-yaw-l" type="fixed">
    <parent link="torso"/>
    <child link="mx28-hip-yaw-l"/>
    <origin rpy="3.141592654 0 3.141592654" xyz="0.018 0.037 -0.04"/>
  </joint>
  <link name="mx28-hip-yaw-l">
    <visual>
      <origin rpy="0 0 0" xyz="0 0 0"/>
      <geometry>
        <mesh filename="package://boldbot_description/meshes/mx28b.stl" scale="0.001 0.001 0.001"/>
      </geometry>
      <material name="DarkGrey">
        <color rgba="0.20 0.20 0.20 1.0"/>
      </material>
    </visual>
    <collision>
      <origin rpy="0 0 0" xyz="0 0 0"/>
      <geometry>
        <mesh filename="package://boldbot_description/meshes/mx28b.stl" scale="0.001 0.001 0.001"/>
      </geometry>
    </collision>
    <inertial>
      <mass value="0.077"/>
      <origin rpy="0 0 0" xyz="0.0105 0 0"/>
      <inertia ixx="1.621883083333333e-05" ixy="0.0" ixz="0.0" iyy="2.451558083333333e-05" iyz="0.0" izz="2.4561203333333333e-05"/>
    </inertial>
  </link>
  <gazebo reference="mx28-hip-yaw-l">
    <material>Gazebo/DarkGrey</material>
    <selfCollide>true</selfCollide>
  </gazebo>
  <joint name="hip-yaw-l" type="revolute">
    <parent link="mx28-hip-yaw-l"/>
    <child link="hip-bracket-l"/>
    <origin rpy="0 0 -1.5707963267948966" xyz="0 0 0.02"/>
    <axis xyz="0 0 1"/>
    <limit effort="2.8" lower="-2.6179939" upper="2.6179939" velocity="5.6548668"/>
    <dynamics damping="0" friction="0.1"/>
  </joint>
  <link name="hip-bracket-l">
    <visual>
      <origin rpy="0 0 0" xyz="0 0 0"/>
      <geometry>
        <mesh filename="package://boldbot_description/meshes/hipbracketb.stl" scale="0.001 0.001 0.001"/>
      </geometry>
    </visual>
    <collision>
      <origin rpy="0 0 0" xyz="0 0 0"/>
      <geometry>
        <mesh filename="package://boldbot_description/meshes/hipbracketb.stl" scale="0.001 0.001 0.001"/>
      </geometry>
    </collision>
    <inertial>
      <mass value="0.025"/>
      <origin rpy="0 0 0" xyz="0 0.003 0.009"/>
      <inertia ixx="7.721354166666668e-06" ixy="0.0" ixz="0.0" iyy="3.927083333333333e-06" iyz="0.0" izz="6.8317708333333345e-06"/>
    </inertial>
    <!-- <inertial> -->
    <!--   <origin xyz="0.000000 0.000480 0.0122437" /> -->
    <!--   <mass value="0.025"/> -->
    <!--   <inertia ixx="0.12259691"  ixy="0.00071127469"  ixz="0.00081143913" -->
    <!--            iyy="0.11066637" iyz="-0.0071635476" -->
    <!--            izz="0.041877668" /> -->
    <!-- </inertial> -->
  </link>
  <joint name="hip-roll-l" type="revolute">
    <parent link="hip-bracket-l"/>
    <child link="mx28-hip-roll-l"/>
    <origin rpy="1.5707963267948966 -1.5707963267948966 0" xyz="0 0.049 0.0315"/>
    <!-- TODO: guessed -->
    <axis xyz="0 0 1"/>
    <limit effort="2.8" lower="-2.6179939" upper="2.6179939" velocity="5.6548668"/>
    <dynamics damping="0" friction="0.1"/>
  </joint>
  <link name="mx28-hip-roll-l">
    <visual>
      <origin rpy="0 0 0" xyz="0 0 0"/>
      <geometry>
        <mesh filename="package://boldbot_description/meshes/mx28b.stl" scale="0.001 0.001 0.001"/>
      </geometry>
      <material name="DarkGrey">
        <color rgba="0.20 0.20 0.20 1.0"/>
      </material>
    </visual>
    <collision>
      <origin rpy="0 0 0" xyz="0 0 0"/>
      <geometry>
        <mesh filename="package://boldbot_description/meshes/mx28b.stl" scale="0.001 0.001 0.001"/>
      </geometry>
    </collision>
    <inertial>
      <mass value="0.077"/>
      <origin rpy="0 0 0" xyz="0.0105 0 0"/>
      <inertia ixx="1.621883083333333e-05" ixy="0.0" ixz="0.0" iyy="2.451558083333333e-05" iyz="0.0" izz="2.4561203333333333e-05"/>
    </inertial>
  </link>
  <gazebo reference="mx28-hip-roll-l">
    <material>Gazebo/DarkGrey</material>
    <selfCollide>true</selfCollide>
  </gazebo>
  <joint name="mx28-hip-roll-mx28-hip-pitch-l" type="fixed">
    <parent link="mx28-hip-roll-l"/>
    <child link="mx28-hip-pitch-l"/>
    <origin rpy="1.5707963267948966 0 0" xyz="0 0 0.05"/>
    <axis xyz="0 0 1"/>
  </joint>
  <link name="mx28-hip-pitch-l">
    <visual>
      <origin rpy="0 0 0" xyz="0 0 0"/>
      <geometry>
        <mesh filename="package://boldbot_description/meshes/mx28b.stl" scale="0.001 0.001 0.001"/>
      </geometry>
      <material name="DarkGrey">
        <color rgba="0.20 0.20 0.20 1.0"/>
      </material>
    </visual>
    <collision>
      <origin rpy="0 0 0" xyz="0 0 0"/>
      <geometry>
        <mesh filename="package://boldbot_description/meshes/mx28b.stl" scale="0.001 0.001 0.001"/>
      </geometry>
    </collision>
    <inertial>
      <mass value="0.077"/>
      <origin rpy="0 0 0" xyz="0.0105 0 0"/>
      <inertia ixx="1.621883083333333e-05" ixy="0.0" ixz="0.0" iyy="2.451558083333333e-05" iyz="0.0" izz="2.4561203333333333e-05"/>
    </inertial>
  </link>
  <gazebo reference="mx28-hip-pitch-l">
    <material>Gazebo/DarkGrey</material>
    <selfCollide>true</selfCollide>
  </gazebo>
  <joint name="hip-pitch-l" type="revolute">
    <parent link="mx28-hip-pitch-l"/>
    <child link="upper-leg-l"/>
    <origin rpy="0 0 0" xyz="0 0 0"/>
    <axis xyz="0 0 1"/>
    <limit effort="2.8" lower="-2.6179939" upper="2.6179939" velocity="5.6548668"/>
    <dynamics damping="0" friction="0.1"/>
  </joint>
  <link name="upper-leg-l">
    <visual>
      <origin rpy="1.5707963267948966 0 0" xyz="0 0 0"/>
      <geometry>
        <mesh filename="package://boldbot_description/meshes/thighb.stl" scale="0.001 0.001 0.001"/>
      </geometry>
    </visual>
    <collision>
      <origin rpy="1.5707963267948966 0 0" xyz="0 0 0"/>
      <geometry>
        <mesh filename="package://boldbot_description/meshes/thighb.stl" scale="0.001 0.001 0.001"/>
      </geometry>
    </collision>
    <inertial>
      <mass value="0.03171796"/>
      <origin rpy="0 0 0" xyz="0.067 0 0"/>
      <inertia ixx="8.662307034166667e-06" ixy="0.0" ixz="0.0" iyy="4.319259282083334e-05" iyz="0.0" izz="3.7834239953333344e-05"/>
    </inertial>
  </link>
  <gazebo reference="upper-leg-l">
    <material>Gazebo/Grey</material>
    <selfCollide>true</selfCollide>
  </gazebo>
  <joint name="upper-leg-mx28-knee-l" type="fixed">
    <parent link="upper-leg-l"/>
    <child link="mx28-knee-l"/>
    <origin rpy="0 0 3.141592653589793" xyz="0.143 0 0"/>
  </joint>
  <link name="mx28-knee-l">
    <visual>
      <origin rpy="0 0 0" xyz="0 0 0"/>
      <geometry>
        <mesh filename="package://boldbot_description/meshes/mx28b.stl" scale="0.001 0.001 0.001"/>
      </geometry>
      <material name="DarkGrey">
        <color rgba="0.20 0.20 0.20 1.0"/>
      </material>
    </visual>
    <collision>
      <origin rpy="0 0 0" xyz="0 0 0"/>
      <geometry>
        <mesh filename="package://boldbot_description/meshes/mx28b.stl" scale="0.001 0.001 0.001"/>
      </geometry>
    </collision>
    <inertial>
      <mass value="0.077"/>
      <origin rpy="0 0 0" xyz="0.0105 0 0"/>
      <inertia ixx="1.621883083333333e-05" ixy="0.0" ixz="0.0" iyy="2.451558083333333e-05" iyz="0.0" izz="2.4561203333333333e-05"/>
    </inertial>
  </link>
  <gazebo reference="mx28-knee-l">
    <material>Gazebo/DarkGrey</material>
    <selfCollide>true</selfCollide>
  </gazebo>
  <joint name="knee-l" type="revolute">
    <parent link="mx28-knee-l"/>
    <child link="lower-leg-l"/>
    <origin rpy="0 0 0" xyz="0 0 0"/>
    <axis xyz="0 0 1"/>
    <limit effort="2.8" lower="-2.6179939" upper="2.6179939" velocity="5.6548668"/>
    <dynamics damping="0" friction="0.1"/>
  </joint>
  <link name="lower-leg-l">
    <visual>
      <origin rpy="1.5707963267948966 0 3.141592653589793" xyz="-0.0175 -0.019 0"/>
      <geometry>
        <mesh filename="package://boldbot_description/meshes/shinb.stl" scale="0.001 0.001 0.001"/>
      </geometry>
    </visual>
    <collision>
      <origin rpy="1.5707963267948966 0 3.141592653589793" xyz="-0.0175 -0.019 0"/>
      <geometry>
        <mesh filename="package://boldbot_description/meshes/shinb.stl" scale="0.001 0.001 0.001"/>
      </geometry>
    </collision>
    <inertial>
      <mass value="0.03431514"/>
      <origin rpy="0 0 0" xyz="-0.07250000000000001 -0.006 0"/>
      <inertia ixx="1.2482132175000002e-05" ixy="0.0" ixz="0.0" iyy="7.658352859375e-05" iyz="0.0" izz="7.419004757875e-05"/>
    </inertial>
  </link>
  <gazebo reference="lower-leg-l">
    <material>Gazebo/Grey</material>
    <selfCollide>true</selfCollide>
  </gazebo>
  <joint name="ankle-pitch-l" type="revolute">
    <parent link="lower-leg-l"/>
    <child link="mx28-ankle-pitch-l"/>
    <origin rpy="3.141592653589793 0 0" xyz="-0.143 0 0"/>
    <axis xyz="0 0 1"/>
    <limit effort="2.8" lower="-2.6179939" upper="2.6179939" velocity="5.6548668"/>
    <dynamics damping="0" friction="0.1"/>
  </joint>
  <link name="mx28-ankle-pitch-l">
    <visual>
      <origin rpy="0 0 0" xyz="0 0 0"/>
      <geometry>
        <mesh filename="package://boldbot_description/meshes/mx28b.stl" scale="0.001 0.001 0.001"/>
      </geometry>
      <material name="DarkGrey">
        <color rgba="0.20 0.20 0.20 1.0"/>
      </material>
    </visual>
    <collision>
      <origin rpy="0 0 0" xyz="0 0 0"/>
      <geometry>
        <mesh filename="package://boldbot_description/meshes/mx28b.stl" scale="0.001 0.001 0.001"/>
      </geometry>
    </collision>
    <inertial>
      <mass value="0.077"/>
      <origin rpy="0 0 0" xyz="0.0105 0 0"/>
      <inertia ixx="1.621883083333333e-05" ixy="0.0" ixz="0.0" iyy="2.451558083333333e-05" iyz="0.0" izz="2.4561203333333333e-05"/>
    </inertial>
  </link>
  <gazebo reference="mx28-ankle-pitch-l">
    <material>Gazebo/DarkGrey</material>
    <selfCollide>true</selfCollide>
  </gazebo>
  <joint name="mx28-ankle-pitch-mx28-ankle-roll-l" type="fixed">
    <parent link="mx28-ankle-pitch-l"/>
    <child link="mx28-ankle-roll-l"/>
    <origin rpy="-1.5707963267948966 0 0" xyz="0 -0.05 0"/>
  </joint>
  <link name="mx28-ankle-roll-l">
    <visual>
      <origin rpy="0 0 0" xyz="0 0 0"/>
      <geometry>
        <mesh filename="package://boldbot_description/meshes/mx28b.stl" scale="0.001 0.001 0.001"/>
      </geometry>
      <material name="DarkGrey">
        <color rgba="0.20 0.20 0.20 1.0"/>
      </material>
    </visual>
    <collision>
      <origin rpy="0 0 0" xyz="0 0 0"/>
      <geometry>
        <mesh filename="package://boldbot_description/meshes/mx28b.stl" scale="0.001 0.001 0.001"/>
      </geometry>
    </collision>
    <inertial>
      <mass value="0.077"/>
      <origin rpy="0 0 0" xyz="0.0105 0 0"/>
      <inertia ixx="1.621883083333333e-05" ixy="0.0" ixz="0.0" iyy="2.451558083333333e-05" iyz="0.0" izz="2.4561203333333333e-05"/>
    </inertial>
  </link>
  <gazebo reference="mx28-ankle-roll-l">
    <material>Gazebo/DarkGrey</material>
    <selfCollide>true</selfCollide>
  </gazebo>
  <joint name="ankle-roll-l" type="revolute">
    <parent link="mx28-ankle-roll-l"/>
    <child link="l_ankle"/>
    <origin rpy="3.141592653589793 -1.5707963267948966 0" xyz="0 0 0.05"/>
    <axis xyz="1 0 0"/>
    <limit effort="2.8" lower="-2.6179939" upper="2.6179939" velocity="5.6548668"/>
    <dynamics damping="0" friction="0.1"/>
  </joint>
  <link name="l_ankle">
    </link>
  <joint name="l_ankle_foot" type="fixed">
    <parent link="l_ankle"/>
    <child link="foot-l"/>
    <origin rpy="0 0 0" xyz="0 0 -0.02"/>
  </joint>
  <link name="foot-l">
    <visual>
      <origin rpy="0 0 -1.5707963267948966" xyz="0 0.01 0"/>
      <!-- TODO: guessed y offset -->
      <geometry>
        <mesh filename="package://boldbot_description/meshes/nicefootlb.stl" scale="0.001 0.001 0.001"/>
      </geometry>
    </visual>
    <collision>
      <origin rpy="0 0 0" xyz="0.013 0.02 0"/>
      <geometry>
        <box size="0.14 0.0935 0.012"/>
      </geometry>
      <!-- <origin xyz="-0.02 ${-lr * 0.01} 0.05" rpy="${pi / 2} 0 ${pi / 2}" /> <!-\- TODO: guessed y offset -\-> -->
      <!-- <geometry> -->
      <!--   <mesh filename="package://boldbot_description/meshes/nicefoot${side}b.stl" scale="0.001 0.001 0.001"/> -->
      <!-- </geometry> -->
    </collision>
    <inertial>
      <mass value="0.03870846"/>
      <origin rpy="0 0 0" xyz="0.013 0.0165 -0.0023"/>
      <inertia ixx="2.866442105625e-05" ixy="0.0" ixz="0.0" iyy="6.368831952000001e-05" iyz="0.0" izz="9.142373753625e-05"/>
    </inertial>
    <!-- <inertial> -->
    <!--   <origin xyz="${-0.02 - 0.0023} ${-lr * (0.01 + 0.0065)} ${0.05 + 0.013}" /> -->
    <!--   <xacro:xmass value="0.1"/> -->
    <!--   <inertia ixx="1e-3"  ixy="0.0"  ixz="0.0" iyy="1e-3" iyz="0.0" izz="1e-3" /> -->
    <!-- </inertial> -->
  </link>
  <gazebo reference="foot-l">
    <material>Gazebo/Grey</material>
    <selfCollide>true</selfCollide>
    <kp>1000000.0</kp>
    <kd>100.0</kd>
    <mu1 value="0.001"/>
    <mu2 value="0.001"/>
    <maxVel>0.5</maxVel>
    <minDepth>0.002</minDepth>
  </gazebo>
  <joint name="l_ankle_sole" type="fixed">
    <parent link="l_ankle"/>
    <child link="l_sole"/>
    <origin rpy="0 0 0" xyz="0.013 0.02 -0.026000000000000002"/>
  </joint>
  <link name="l_sole">
    </link>
  <joint name="l_sole_toe" type="fixed">
    <parent link="l_sole"/>
    <child link="l_toe"/>
    <origin rpy="0 0 0" xyz="0.07 0 0"/>
  </joint>
  <link name="l_toe">
    </link>
  <joint name="torso-mx28-hip-yaw-r" type="fixed">
    <parent link="torso"/>
    <child link="mx28-hip-yaw-r"/>
    <origin rpy="-3.141592654 0 3.141592654" xyz="0.018 -0.037 -0.04"/>
  </joint>
  <link name="mx28-hip-yaw-r">
    <visual>
      <origin rpy="0 0 0" xyz="0 0 0"/>
      <geometry>
        <mesh filename="package://boldbot_description/meshes/mx28b.stl" scale="0.001 0.001 0.001"/>
      </geometry>
      <material name="DarkGrey">
        <color rgba="0.20 0.20 0.20 1.0"/>
      </material>
    </visual>
    <collision>
      <origin rpy="0 0 0" xyz="0 0 0"/>
      <geometry>
        <mesh filename="package://boldbot_description/meshes/mx28b.stl" scale="0.001 0.001 0.001"/>
      </geometry>
    </collision>
    <inertial>
      <mass value="0.077"/>
      <origin rpy="0 0 0" xyz="0.0105 0 0"/>
      <inertia ixx="1.621883083333333e-05" ixy="0.0" ixz="0.0" iyy="2.451558083333333e-05" iyz="0.0" izz="2.4561203333333333e-05"/>
    </inertial>
  </link>
  <gazebo reference="mx28-hip-yaw-r">
    <material>Gazebo/DarkGrey</material>
    <selfCollide>true</selfCollide>
  </gazebo>
  <joint name="hip-yaw-r" type="revolute">
    <parent link="mx28-hip-yaw-r"/>
    <child link="hip-bracket-r"/>
    <origin rpy="0 0 -1.5707963267948966" xyz="0 0 0.02"/>
    <axis xyz="0 0 1"/>
    <limit effort="2.8" lower="-2.6179939" upper="2.6179939" velocity="5.6548668"/>
    <dynamics damping="0" friction="0.1"/>
  </joint>
  <link name="hip-bracket-r">
    <visual>
      <origin rpy="0 0 0" xyz="0 0 0"/>
      <geometry>
        <mesh filename="package://boldbot_description/meshes/hipbracketb.stl" scale="0.001 0.001 0.001"/>
      </geometry>
    </visual>
    <collision>
      <origin rpy="0 0 0" xyz="0 0 0"/>
      <geometry>
        <mesh filename="package://boldbot_description/meshes/hipbracketb.stl" scale="0.001 0.001 0.001"/>
      </geometry>
    </collision>
    <inertial>
      <mass value="0.025"/>
      <origin rpy="0 0 0" xyz="0 0.003 0.009"/>
      <inertia ixx="7.721354166666668e-06" ixy="0.0" ixz="0.0" iyy="3.927083333333333e-06" iyz="0.0" izz="6.8317708333333345e-06"/>
    </inertial>
    <!-- <inertial> -->
    <!--   <origin xyz="0.000000 0.000480 0.0122437" /> -->
    <!--   <mass value="0.025"/> -->
    <!--   <inertia ixx="0.12259691"  ixy="0.00071127469"  ixz="0.00081143913" -->
    <!--            iyy="0.11066637" iyz="-0.0071635476" -->
    <!--            izz="0.041877668" /> -->
    <!-- </inertial> -->
  </link>
  <joint name="hip-roll-r" type="revolute">
    <parent link="hip-bracket-r"/>
    <child link="mx28-hip-roll-r"/>
    <origin rpy="1.5707963267948966 -1.5707963267948966 0" xyz="0 0.049 0.0315"/>
    <!-- TODO: guessed -->
    <axis xyz="0 0 1"/>
    <limit effort="2.8" lower="-2.6179939" upper="2.6179939" velocity="5.6548668"/>
    <dynamics damping="0" friction="0.1"/>
  </joint>
  <link name="mx28-hip-roll-r">
    <visual>
      <origin rpy="0 0 0" xyz="0 0 0"/>
      <geometry>
        <mesh filename="package://boldbot_description/meshes/mx28b.stl" scale="0.001 0.001 0.001"/>
      </geometry>
      <material name="DarkGrey">
        <color rgba="0.20 0.20 0.20 1.0"/>
      </material>
    </visual>
    <collision>
      <origin rpy="0 0 0" xyz="0 0 0"/>
      <geometry>
        <mesh filename="package://boldbot_description/meshes/mx28b.stl" scale="0.001 0.001 0.001"/>
      </geometry>
    </collision>
    <inertial>
      <mass value="0.077"/>
      <origin rpy="0 0 0" xyz="0.0105 0 0"/>
      <inertia ixx="1.621883083333333e-05" ixy="0.0" ixz="0.0" iyy="2.451558083333333e-05" iyz="0.0" izz="2.4561203333333333e-05"/>
    </inertial>
  </link>
  <gazebo reference="mx28-hip-roll-r">
    <material>Gazebo/DarkGrey</material>
    <selfCollide>true</selfCollide>
  </gazebo>
  <joint name="mx28-hip-roll-mx28-hip-pitch-r" type="fixed">
    <parent link="mx28-hip-roll-r"/>
    <child link="mx28-hip-pitch-r"/>
    <origin rpy="-1.5707963267948966 0 0" xyz="0 0 0.05"/>
    <axis xyz="0 0 1"/>
  </joint>
  <link name="mx28-hip-pitch-r">
    <visual>
      <origin rpy="0 0 0" xyz="0 0 0"/>
      <geometry>
        <mesh filename="package://boldbot_description/meshes/mx28b.stl" scale="0.001 0.001 0.001"/>
      </geometry>
      <material name="DarkGrey">
        <color rgba="0.20 0.20 0.20 1.0"/>
      </material>
    </visual>
    <collision>
      <origin rpy="0 0 0" xyz="0 0 0"/>
      <geometry>
        <mesh filename="package://boldbot_description/meshes/mx28b.stl" scale="0.001 0.001 0.001"/>
      </geometry>
    </collision>
    <inertial>
      <mass value="0.077"/>
      <origin rpy="0 0 0" xyz="0.0105 0 0"/>
      <inertia ixx="1.621883083333333e-05" ixy="0.0" ixz="0.0" iyy="2.451558083333333e-05" iyz="0.0" izz="2.4561203333333333e-05"/>
    </inertial>
  </link>
  <gazebo reference="mx28-hip-pitch-r">
    <material>Gazebo/DarkGrey</material>
    <selfCollide>true</selfCollide>
  </gazebo>
  <joint name="hip-pitch-r" type="revolute">
    <parent link="mx28-hip-pitch-r"/>
    <child link="upper-leg-r"/>
    <origin rpy="0 0 0" xyz="0 0 0"/>
    <axis xyz="0 0 1"/>
    <limit effort="2.8" lower="-2.6179939" upper="2.6179939" velocity="5.6548668"/>
    <dynamics damping="0" friction="0.1"/>
  </joint>
  <link name="upper-leg-r">
    <visual>
      <origin rpy="1.5707963267948966 0 0" xyz="0 0 0"/>
      <geometry>
        <mesh filename="package://boldbot_description/meshes/thighb.stl" scale="0.001 0.001 0.001"/>
      </geometry>
    </visual>
    <collision>
      <origin rpy="1.5707963267948966 0 0" xyz="0 0 0"/>
      <geometry>
        <mesh filename="package://boldbot_description/meshes/thighb.stl" scale="0.001 0.001 0.001"/>
      </geometry>
    </collision>
    <inertial>
      <mass value="0.03171796"/>
      <origin rpy="0 0 0" xyz="0.067 0 0"/>
      <inertia ixx="8.662307034166667e-06" ixy="0.0" ixz="0.0" iyy="4.319259282083334e-05" iyz="0.0" izz="3.7834239953333344e-05"/>
    </inertial>
  </link>
  <gazebo reference="upper-leg-r">
    <material>Gazebo/Grey</material>
    <selfCollide>true</selfCollide>
  </gazebo>
  <joint name="upper-leg-mx28-knee-r" type="fixed">
    <parent link="upper-leg-r"/>
    <child link="mx28-knee-r"/>
    <origin rpy="0 0 3.141592653589793" xyz="0.143 0 0"/>
  </joint>
  <link name="mx28-knee-r">
    <visual>
      <origin rpy="0 0 0" xyz="0 0 0"/>
      <geometry>
        <mesh filename="package://boldbot_description/meshes/mx28b.stl" scale="0.001 0.001 0.001"/>
      </geometry>
      <material name="DarkGrey">
        <color rgba="0.20 0.20 0.20 1.0"/>
      </material>
    </visual>
    <collision>
      <origin rpy="0 0 0" xyz="0 0 0"/>
      <geometry>
        <mesh filename="package://boldbot_description/meshes/mx28b.stl" scale="0.001 0.001 0.001"/>
      </geometry>
    </collision>
    <inertial>
      <mass value="0.077"/>
      <origin rpy="0 0 0" xyz="0.0105 0 0"/>
      <inertia ixx="1.621883083333333e-05" ixy="0.0" ixz="0.0" iyy="2.451558083333333e-05" iyz="0.0" izz="2.4561203333333333e-05"/>
    </inertial>
  </link>
  <gazebo reference="mx28-knee-r">
    <material>Gazebo/DarkGrey</material>
    <selfCollide>true</selfCollide>
  </gazebo>
  <joint name="knee-r" type="revolute">
    <parent link="mx28-knee-r"/>
    <child link="lower-leg-r"/>
    <origin rpy="0 0 0" xyz="0 0 0"/>
    <axis xyz="0 0 1"/>
    <limit effort="2.8" lower="-2.6179939" upper="2.6179939" velocity="5.6548668"/>
    <dynamics damping="0" friction="0.1"/>
  </joint>
  <link name="lower-leg-r">
    <visual>
      <origin rpy="-1.5707963267948966 0 3.141592653589793" xyz="-0.0175 0.019 0"/>
      <geometry>
        <mesh filename="package://boldbot_description/meshes/shinb.stl" scale="0.001 0.001 0.001"/>
      </geometry>
    </visual>
    <collision>
      <origin rpy="-1.5707963267948966 0 3.141592653589793" xyz="-0.0175 0.019 0"/>
      <geometry>
        <mesh filename="package://boldbot_description/meshes/shinb.stl" scale="0.001 0.001 0.001"/>
      </geometry>
    </collision>
    <inertial>
      <mass value="0.03431514"/>
      <origin rpy="0 0 0" xyz="-0.07250000000000001 0.006 0"/>
      <inertia ixx="1.2482132175000002e-05" ixy="0.0" ixz="0.0" iyy="7.658352859375e-05" iyz="0.0" izz="7.419004757875e-05"/>
    </inertial>
  </link>
  <gazebo reference="lower-leg-r">
    <material>Gazebo/Grey</material>
    <selfCollide>true</selfCollide>
  </gazebo>
  <joint name="ankle-pitch-r" type="revolute">
    <parent link="lower-leg-r"/>
    <child link="mx28-ankle-pitch-r"/>
    <origin rpy="3.141592653589793 0 0" xyz="-0.143 0 0"/>
    <axis xyz="0 0 1"/>
    <limit effort="2.8" lower="-2.6179939" upper="2.6179939" velocity="5.6548668"/>
    <dynamics damping="0" friction="0.1"/>
  </joint>
  <link name="mx28-ankle-pitch-r">
    <visual>
      <origin rpy="0 0 0" xyz="0 0 0"/>
      <geometry>
        <mesh filename="package://boldbot_description/meshes/mx28b.stl" scale="0.001 0.001 0.001"/>
      </geometry>
      <material name="DarkGrey">
        <color rgba="0.20 0.20 0.20 1.0"/>
      </material>
    </visual>
    <collision>
      <origin rpy="0 0 0" xyz="0 0 0"/>
      <geometry>
        <mesh filename="package://boldbot_description/meshes/mx28b.stl" scale="0.001 0.001 0.001"/>
      </geometry>
    </collision>
    <inertial>
      <mass value="0.077"/>
      <origin rpy="0 0 0" xyz="0.0105 0 0"/>
      <inertia ixx="1.621883083333333e-05" ixy="0.0" ixz="0.0" iyy="2.451558083333333e-05" iyz="0.0" izz="2.4561203333333333e-05"/>
    </inertial>
  </link>
  <gazebo reference="mx28-ankle-pitch-r">
    <material>Gazebo/DarkGrey</material>
    <selfCollide>true</selfCollide>
  </gazebo>
  <joint name="mx28-ankle-pitch-mx28-ankle-roll-r" type="fixed">
    <parent link="mx28-ankle-pitch-r"/>
    <child link="mx28-ankle-roll-r"/>
    <origin rpy="1.5707963267948966 0 0" xyz="0 0.05 0"/>
  </joint>
  <link name="mx28-ankle-roll-r">
    <visual>
      <origin rpy="0 0 0" xyz="0 0 0"/>
      <geometry>
        <mesh filename="package://boldbot_description/meshes/mx28b.stl" scale="0.001 0.001 0.001"/>
      </geometry>
      <material name="DarkGrey">
        <color rgba="0.20 0.20 0.20 1.0"/>
      </material>
    </visual>
    <collision>
      <origin rpy="0 0 0" xyz="0 0 0"/>
      <geometry>
        <mesh filename="package://boldbot_description/meshes/mx28b.stl" scale="0.001 0.001 0.001"/>
      </geometry>
    </collision>
    <inertial>
      <mass value="0.077"/>
      <origin rpy="0 0 0" xyz="0.0105 0 0"/>
      <inertia ixx="1.621883083333333e-05" ixy="0.0" ixz="0.0" iyy="2.451558083333333e-05" iyz="0.0" izz="2.4561203333333333e-05"/>
    </inertial>
  </link>
  <gazebo reference="mx28-ankle-roll-r">
    <material>Gazebo/DarkGrey</material>
    <selfCollide>true</selfCollide>
  </gazebo>
  <joint name="ankle-roll-r" type="revolute">
    <parent link="mx28-ankle-roll-r"/>
    <child link="r_ankle"/>
    <origin rpy="-3.141592653589793 -1.5707963267948966 0" xyz="0 0 0.05"/>
    <axis xyz="1 0 0"/>
    <limit effort="2.8" lower="-2.6179939" upper="2.6179939" velocity="5.6548668"/>
    <dynamics damping="0" friction="0.1"/>
  </joint>
  <link name="r_ankle">
    </link>
  <joint name="r_ankle_foot" type="fixed">
    <parent link="r_ankle"/>
    <child link="foot-r"/>
    <origin rpy="0 0 0" xyz="0 0 -0.02"/>
  </joint>
  <link name="foot-r">
    <visual>
      <origin rpy="0 0 -1.5707963267948966" xyz="0 -0.01 0"/>
      <!-- TODO: guessed y offset -->
      <geometry>
        <mesh filename="package://boldbot_description/meshes/nicefootrb.stl" scale="0.001 0.001 0.001"/>
      </geometry>
    </visual>
    <collision>
      <origin rpy="0 0 0" xyz="0.013 -0.02 0"/>
      <geometry>
        <box size="0.14 0.0935 0.012"/>
      </geometry>
      <!-- <origin xyz="-0.02 ${-lr * 0.01} 0.05" rpy="${pi / 2} 0 ${pi / 2}" /> <!-\- TODO: guessed y offset -\-> -->
      <!-- <geometry> -->
      <!--   <mesh filename="package://boldbot_description/meshes/nicefoot${side}b.stl" scale="0.001 0.001 0.001"/> -->
      <!-- </geometry> -->
    </collision>
    <inertial>
      <mass value="0.03870846"/>
      <origin rpy="0 0 0" xyz="0.013 -0.0165 -0.0023"/>
      <inertia ixx="2.866442105625e-05" ixy="0.0" ixz="0.0" iyy="6.368831952000001e-05" iyz="0.0" izz="9.142373753625e-05"/>
    </inertial>
    <!-- <inertial> -->
    <!--   <origin xyz="${-0.02 - 0.0023} ${-lr * (0.01 + 0.0065)} ${0.05 + 0.013}" /> -->
    <!--   <xacro:xmass value="0.1"/> -->
    <!--   <inertia ixx="1e-3"  ixy="0.0"  ixz="0.0" iyy="1e-3" iyz="0.0" izz="1e-3" /> -->
    <!-- </inertial> -->
  </link>
  <gazebo reference="foot-r">
    <material>Gazebo/Grey</material>
    <selfCollide>true</selfCollide>
    <kp>1000000.0</kp>
    <kd>100.0</kd>
    <mu1 value="0.001"/>
    <mu2 value="0.001"/>
    <maxVel>0.5</maxVel>
    <minDepth>0.002</minDepth>
  </gazebo>
  <joint name="r_ankle_sole" type="fixed">
    <parent link="r_ankle"/>
    <child link="r_sole"/>
    <origin rpy="0 0 0" xyz="0.013 -0.02 -0.026000000000000002"/>
  </joint>
  <link name="r_sole">
    </link>
  <joint name="r_sole_toe" type="fixed">
    <parent link="r_sole"/>
    <child link="r_toe"/>
    <origin rpy="0 0 0" xyz="0.07 0 0"/>
  </joint>
  <link name="r_toe">
    </link>

  <joint name="base_footprint_j" type="fixed">
    <parent link="base_footprint"/>
    <child link="base_link"/>
    <origin rpy="0 0 0" xyz="0.07 0 0"/>
  </joint>
  <link name="base_footprint">
  </link>
  <gazebo>
    <plugin filename="libboldbot_gazebo_plugin.so" name="boldbot_gazebo">
    </plugin>
  </gazebo>

  <gazebo reference="head">
      <sensor name="camera_depth" type="depth">
        <always_on>1</always_on>
        <update_rate>1</update_rate>
        <pose>0 0 0 0 0 0</pose>
        <camera name="camera_depth">
        </camera>
	          <plugin name="camera_driver" filename="libgazebo_ros_camera.so">
            <camera_name>camera_depth</camera_name>
            <frame_name>camera_depth</frame_name>
            <hack_baseline>0.07</hack_baseline>
            <min_depth>0.001</min_depth>
          </plugin>
      </sensor>
  </gazebo>
  <gazebo reference="head">
      <sensor name="camera_rgb" type="camera">
        <always_on>true</always_on>
        <visualize>true</visualize>
        <update_rate>30</update_rate>
	      <pose>0 0 0 0 0 0</pose>
        <camera name="camera_rgb">
          <horizontal_fov>1.02974</horizontal_fov>
          <image>
            <width>320</width>
            <height>240</height>
            <format>R8G8B8</format>
          </image>
          <clip>
            <near>0.02</near>
            <far>300</far>
          </clip>
          <noise>
            <type>gaussian</type>
            <mean>0.0</mean>
            <stddev>0.007</stddev>
          </noise>
        </camera>
          <plugin name="camera_driver" filename="libgazebo_ros_camera.so">
            <camera_name>camera_rgb</camera_name>
            <frame_name>camera_rgb</frame_name>
            <hack_baseline>0.07</hack_baseline>
          </plugin>
      </sensor>
  </gazebo>
  <gazebo reference="torso">
    <gravity>true</gravity>
    <sensor name="imu_sensor" type="imu">
      <always_on>true</always_on>
      <update_rate>125</update_rate>
      <!-- <visualize>true</visualize> -->
      <topic>__default_topic__</topic>
      <plugin filename="libgazebo_ros_imu_sensor.so" name="imu_plugin">
        <ros>
          <argument>~/out:=/imu/data_raw</argument>
        </ros>
        <bodyName>torso</bodyName>
        <gaussianNoise>0.0</gaussianNoise>
      </plugin>
      <pose>0 0 0 0 0 0</pose>
    </sensor>
  </gazebo>
  <gazebo>
    <plugin filename="libgazebo_ros_planar_move.so" name="object_controller">
      <ros>
        <argument>odom:=odom_cmd</argument>
      </ros>
      <publish_odom>true</publish_odom>
      <publish_odom_tf>true</publish_odom_tf>

      <odometry_frame>odom_cmd</odometry_frame>
      <robot_base_frame>base_link</robot_base_frame>

      <covariance_x>0.0001</covariance_x>
      <covariance_y>0.0001</covariance_y>
      <covariance_yaw>0.01</covariance_yaw>
    </plugin>
  </gazebo>
</robot>
